{"level":"ERROR","location":"[get_call:118] fyersModel","message":"Extra data: line 1 column 59 (char 58)","timestamp":"2023-12-23 23:17:52,504+0530","service":"FyersDataSocket"}
{"level":"ERROR","location":"[get_call:118] fyersModel","message":"Extra data: line 1 column 59 (char 58)","timestamp":"2023-12-23 23:18:12,544+0530","service":"FyersDataSocket"}
{"level":"ERROR","location":"[get_call:118] fyersModel","message":"Extra data: line 1 column 59 (char 58)","timestamp":"2023-12-23 23:19:30,199+0530","service":"FyersDataSocket"}
{"level":"ERROR","location":"[get_call:118] fyersModel","message":"Extra data: line 1 column 59 (char 58)","timestamp":"2023-12-23 23:19:45,490+0530","service":"FyersDataSocket"}
{"level":"ERROR","location":"[get_call:118] fyersModel","message":"Extra data: line 1 column 59 (char 58)","timestamp":"2023-12-23 23:20:29,916+0530","service":"FyersDataSocket"}
{"level":"ERROR","location":"[get_call:118] fyersModel","message":"Extra data: line 1 column 59 (char 58)","timestamp":"2023-12-28 20:01:22,652+0530","service":"FyersDataSocket"}
{"level":"ERROR","location":"[On_message:1427] data_ws","message":"'symbol'","timestamp":"2023-12-29 10:33:54,271+0530","service":"FyersDataSocket","exception":"Traceback (most recent call last):\n  File \"C:\\Python\\Lib\\site-packages\\fyers_apiv3\\FyersWebsocket\\data_ws.py\", line 1418, in On_message\n    self.OnMessage(message)\n  File \"C:\\Users\\jaypa\\AppData\\Local\\Temp\\ipykernel_4692\\3885875142.py\", line 5, in onmessage\n    if message['symbol']== 'NSE:SBIN-EQ' and message['ltp'] > 610:\n       ~~~~~~~^^^^^^^^^^\nKeyError: 'symbol'","exception_name":"KeyError"}
{"level":"ERROR","location":"[On_message:1427] data_ws","message":"'symbol'","timestamp":"2023-12-29 10:33:54,307+0530","service":"FyersDataSocket","exception":"Traceback (most recent call last):\n  File \"C:\\Python\\Lib\\site-packages\\fyers_apiv3\\FyersWebsocket\\data_ws.py\", line 1418, in On_message\n    self.OnMessage(message)\n  File \"C:\\Users\\jaypa\\AppData\\Local\\Temp\\ipykernel_4692\\3885875142.py\", line 5, in onmessage\n    if message['symbol']== 'NSE:SBIN-EQ' and message['ltp'] > 610:\n       ~~~~~~~^^^^^^^^^^\nKeyError: 'symbol'","exception_name":"KeyError"}
{"level":"ERROR","location":"[On_message:1427] data_ws","message":"'symbol'","timestamp":"2023-12-29 10:33:56,275+0530","service":"FyersDataSocket","exception":"Traceback (most recent call last):\n  File \"C:\\Python\\Lib\\site-packages\\fyers_apiv3\\FyersWebsocket\\data_ws.py\", line 1418, in On_message\n    self.OnMessage(message)\n  File \"C:\\Users\\jaypa\\AppData\\Local\\Temp\\ipykernel_4692\\3885875142.py\", line 5, in onmessage\n    if message['symbol']== 'NSE:SBIN-EQ' and message['ltp'] > 610:\n       ~~~~~~~^^^^^^^^^^\nKeyError: 'symbol'","exception_name":"KeyError"}
{"level":"ERROR","location":"[On_message:1427] data_ws","message":"'symbol'","timestamp":"2023-12-29 10:33:56,459+0530","service":"FyersDataSocket","exception":"Traceback (most recent call last):\n  File \"C:\\Python\\Lib\\site-packages\\fyers_apiv3\\FyersWebsocket\\data_ws.py\", line 1418, in On_message\n    self.OnMessage(message)\n  File \"C:\\Users\\jaypa\\AppData\\Local\\Temp\\ipykernel_4692\\3885875142.py\", line 5, in onmessage\n    if message['symbol']== 'NSE:SBIN-EQ' and message['ltp'] > 610:\n       ~~~~~~~^^^^^^^^^^\nKeyError: 'symbol'","exception_name":"KeyError"}
{"level":"ERROR","location":"[On_message:1427] data_ws","message":"'symbol'","timestamp":"2023-12-29 10:35:31,191+0530","service":"FyersDataSocket","exception":"Traceback (most recent call last):\n  File \"C:\\Python\\Lib\\site-packages\\fyers_apiv3\\FyersWebsocket\\data_ws.py\", line 1418, in On_message\n    self.OnMessage(message)\n  File \"C:\\Users\\jaypa\\AppData\\Local\\Temp\\ipykernel_4692\\3885875142.py\", line 5, in onmessage\n    if message['symbol']== 'NSE:SBIN-EQ' and message['ltp'] > 610:\n       ~~~~~~~^^^^^^^^^^\nKeyError: 'symbol'","exception_name":"KeyError"}
{"level":"ERROR","location":"[On_message:1427] data_ws","message":"'symbol'","timestamp":"2023-12-29 10:35:44,773+0530","service":"FyersDataSocket","exception":"Traceback (most recent call last):\n  File \"C:\\Python\\Lib\\site-packages\\fyers_apiv3\\FyersWebsocket\\data_ws.py\", line 1418, in On_message\n    self.OnMessage(message)\n  File \"C:\\Users\\jaypa\\AppData\\Local\\Temp\\ipykernel_4692\\3885875142.py\", line 5, in onmessage\n    if message['symbol']== 'NSE:SBIN-EQ' and message['ltp'] > 610:\n       ~~~~~~~^^^^^^^^^^\nKeyError: 'symbol'","exception_name":"KeyError"}
{"level":"ERROR","location":"[On_message:1427] data_ws","message":"'ltp'","timestamp":"2023-12-29 10:50:28,620+0530","service":"FyersDataSocket","exception":"Traceback (most recent call last):\n  File \"C:\\Python\\Lib\\site-packages\\fyers_apiv3\\FyersWebsocket\\data_ws.py\", line 1418, in On_message\n    self.OnMessage(message)\n  File \"C:\\Users\\jaypa\\AppData\\Local\\Temp\\ipykernel_4692\\3830732828.py\", line 4, in onmessage\n    print(\"Response:\", message['ltp'])\n                       ~~~~~~~^^^^^^^\nKeyError: 'ltp'","exception_name":"KeyError"}
{"level":"ERROR","location":"[On_message:1427] data_ws","message":"'ltp'","timestamp":"2023-12-29 10:50:28,660+0530","service":"FyersDataSocket","exception":"Traceback (most recent call last):\n  File \"C:\\Python\\Lib\\site-packages\\fyers_apiv3\\FyersWebsocket\\data_ws.py\", line 1418, in On_message\n    self.OnMessage(message)\n  File \"C:\\Users\\jaypa\\AppData\\Local\\Temp\\ipykernel_4692\\3830732828.py\", line 4, in onmessage\n    print(\"Response:\", message['ltp'])\n                       ~~~~~~~^^^^^^^\nKeyError: 'ltp'","exception_name":"KeyError"}
{"level":"ERROR","location":"[On_message:1427] data_ws","message":"'ltp'","timestamp":"2023-12-29 10:50:30,694+0530","service":"FyersDataSocket","exception":"Traceback (most recent call last):\n  File \"C:\\Python\\Lib\\site-packages\\fyers_apiv3\\FyersWebsocket\\data_ws.py\", line 1418, in On_message\n    self.OnMessage(message)\n  File \"C:\\Users\\jaypa\\AppData\\Local\\Temp\\ipykernel_4692\\3830732828.py\", line 4, in onmessage\n    print(\"Response:\", message['ltp'])\n                       ~~~~~~~^^^^^^^\nKeyError: 'ltp'","exception_name":"KeyError"}
{"level":"ERROR","location":"[On_message:1427] data_ws","message":"'ltp'","timestamp":"2023-12-29 10:51:14,068+0530","service":"FyersDataSocket","exception":"Traceback (most recent call last):\n  File \"C:\\Python\\Lib\\site-packages\\fyers_apiv3\\FyersWebsocket\\data_ws.py\", line 1418, in On_message\n    self.OnMessage(message)\n  File \"C:\\Users\\jaypa\\AppData\\Local\\Temp\\ipykernel_4692\\3830732828.py\", line 4, in onmessage\n    print(\"Response:\", message['ltp'])\n                       ~~~~~~~^^^^^^^\nKeyError: 'ltp'","exception_name":"KeyError"}
{"level":"ERROR","location":"[get_call:118] fyersModel","message":"HTTPSConnectionPool(host='api-t1.fyers.in', port=443): Max retries exceeded with url: /data/history?symbol=NSE%3ANIFTY50-INDEX&resolution=15&date_format=1&range_from=2023-09-20&range_to=2023-12-29&cont_flag=0 (Caused by NameResolutionError(\"<urllib3.connection.HTTPSConnection object at 0x0000017764F5AF50>: Failed to resolve 'api-t1.fyers.in' ([Errno 11001] getaddrinfo failed)\"))","timestamp":"2023-12-29 16:15:07,469+0530","service":"FyersDataSocket"}
{"level":"ERROR","location":"[On_message:1427] data_ws","message":"'ltp'","timestamp":"2023-12-29 19:51:49,185+0530","service":"FyersDataSocket","exception":"Traceback (most recent call last):\n  File \"C:\\Python\\Lib\\site-packages\\fyers_apiv3\\FyersWebsocket\\data_ws.py\", line 1418, in On_message\n    self.OnMessage(message)\n  File \"C:\\Users\\jaypa\\AppData\\Local\\Temp\\ipykernel_13716\\1689538537.py\", line 2, in Live_data\n    ltp = data['ltp']\n          ~~~~^^^^^^^\nKeyError: 'ltp'","exception_name":"KeyError"}
{"level":"ERROR","location":"[On_message:1427] data_ws","message":"'ltp'","timestamp":"2023-12-29 19:51:49,235+0530","service":"FyersDataSocket","exception":"Traceback (most recent call last):\n  File \"C:\\Python\\Lib\\site-packages\\fyers_apiv3\\FyersWebsocket\\data_ws.py\", line 1418, in On_message\n    self.OnMessage(message)\n  File \"C:\\Users\\jaypa\\AppData\\Local\\Temp\\ipykernel_13716\\1689538537.py\", line 2, in Live_data\n    ltp = data['ltp']\n          ~~~~^^^^^^^\nKeyError: 'ltp'","exception_name":"KeyError"}
{"level":"ERROR","location":"[On_message:1427] data_ws","message":"'ltp'","timestamp":"2023-12-29 19:51:51,213+0530","service":"FyersDataSocket","exception":"Traceback (most recent call last):\n  File \"C:\\Python\\Lib\\site-packages\\fyers_apiv3\\FyersWebsocket\\data_ws.py\", line 1418, in On_message\n    self.OnMessage(message)\n  File \"C:\\Users\\jaypa\\AppData\\Local\\Temp\\ipykernel_13716\\1689538537.py\", line 2, in Live_data\n    ltp = data['ltp']\n          ~~~~^^^^^^^\nKeyError: 'ltp'","exception_name":"KeyError"}
{"level":"ERROR","location":"[On_message:1427] data_ws","message":"'ltp'","timestamp":"2023-12-29 19:52:08,051+0530","service":"FyersDataSocket","exception":"Traceback (most recent call last):\n  File \"C:\\Python\\Lib\\site-packages\\fyers_apiv3\\FyersWebsocket\\data_ws.py\", line 1418, in On_message\n    self.OnMessage(message)\n  File \"C:\\Users\\jaypa\\AppData\\Local\\Temp\\ipykernel_13716\\2954393528.py\", line 4, in onmessage\n    print(\"Response:\", message['ltp'])\n                       ~~~~~~~^^^^^^^\nKeyError: 'ltp'","exception_name":"KeyError"}
{"level":"ERROR","location":"[On_message:1427] data_ws","message":"'ltp'","timestamp":"2023-12-29 19:52:08,057+0530","service":"FyersDataSocket","exception":"Traceback (most recent call last):\n  File \"C:\\Python\\Lib\\site-packages\\fyers_apiv3\\FyersWebsocket\\data_ws.py\", line 1418, in On_message\n    self.OnMessage(message)\n  File \"C:\\Users\\jaypa\\AppData\\Local\\Temp\\ipykernel_13716\\2954393528.py\", line 4, in onmessage\n    print(\"Response:\", message['ltp'])\n                       ~~~~~~~^^^^^^^\nKeyError: 'ltp'","exception_name":"KeyError"}
{"level":"ERROR","location":"[On_message:1427] data_ws","message":"'ltp'","timestamp":"2023-12-29 19:52:10,070+0530","service":"FyersDataSocket","exception":"Traceback (most recent call last):\n  File \"C:\\Python\\Lib\\site-packages\\fyers_apiv3\\FyersWebsocket\\data_ws.py\", line 1418, in On_message\n    self.OnMessage(message)\n  File \"C:\\Users\\jaypa\\AppData\\Local\\Temp\\ipykernel_13716\\2954393528.py\", line 4, in onmessage\n    print(\"Response:\", message['ltp'])\n                       ~~~~~~~^^^^^^^\nKeyError: 'ltp'","exception_name":"KeyError"}
{"level":"ERROR","location":"[On_message:1427] data_ws","message":"'ltp'","timestamp":"2023-12-29 19:52:26,893+0530","service":"FyersDataSocket","exception":"Traceback (most recent call last):\n  File \"C:\\Python\\Lib\\site-packages\\fyers_apiv3\\FyersWebsocket\\data_ws.py\", line 1418, in On_message\n    self.OnMessage(message)\n  File \"C:\\Users\\jaypa\\AppData\\Local\\Temp\\ipykernel_13716\\2954393528.py\", line 4, in onmessage\n    print(\"Response:\", message['ltp'])\n                       ~~~~~~~^^^^^^^\nKeyError: 'ltp'","exception_name":"KeyError"}
{"level":"ERROR","location":"[On_message:1431] data_ws","message":"name 'data' is not defined","timestamp":"2023-12-29 19:53:13,876+0530","service":"FyersDataSocket","exception":"Traceback (most recent call last):\n  File \"C:\\Python\\Lib\\site-packages\\fyers_apiv3\\FyersWebsocket\\data_ws.py\", line 1418, in On_message\n    self.OnMessage(message)\n  File \"C:\\Users\\jaypa\\AppData\\Local\\Temp\\ipykernel_13716\\1998671309.py\", line 4, in onmessage\n    Live_data(data)\n              ^^^^\nNameError: name 'data' is not defined","exception_name":"NameError"}
{"level":"ERROR","location":"[On_message:1431] data_ws","message":"name 'data' is not defined","timestamp":"2023-12-29 19:53:13,881+0530","service":"FyersDataSocket","exception":"Traceback (most recent call last):\n  File \"C:\\Python\\Lib\\site-packages\\fyers_apiv3\\FyersWebsocket\\data_ws.py\", line 1418, in On_message\n    self.OnMessage(message)\n  File \"C:\\Users\\jaypa\\AppData\\Local\\Temp\\ipykernel_13716\\1998671309.py\", line 4, in onmessage\n    Live_data(data)\n              ^^^^\nNameError: name 'data' is not defined","exception_name":"NameError"}
{"level":"ERROR","location":"[On_message:1431] data_ws","message":"name 'data' is not defined","timestamp":"2023-12-29 19:53:15,940+0530","service":"FyersDataSocket","exception":"Traceback (most recent call last):\n  File \"C:\\Python\\Lib\\site-packages\\fyers_apiv3\\FyersWebsocket\\data_ws.py\", line 1418, in On_message\n    self.OnMessage(message)\n  File \"C:\\Users\\jaypa\\AppData\\Local\\Temp\\ipykernel_13716\\1998671309.py\", line 4, in onmessage\n    Live_data(data)\n              ^^^^\nNameError: name 'data' is not defined","exception_name":"NameError"}
{"level":"ERROR","location":"[On_message:1431] data_ws","message":"name 'data' is not defined","timestamp":"2023-12-29 19:53:15,943+0530","service":"FyersDataSocket","exception":"Traceback (most recent call last):\n  File \"C:\\Python\\Lib\\site-packages\\fyers_apiv3\\FyersWebsocket\\data_ws.py\", line 1418, in On_message\n    self.OnMessage(message)\n  File \"C:\\Users\\jaypa\\AppData\\Local\\Temp\\ipykernel_13716\\1998671309.py\", line 4, in onmessage\n    Live_data(data)\n              ^^^^\nNameError: name 'data' is not defined","exception_name":"NameError"}
{"level":"ERROR","location":"[On_message:1427] data_ws","message":"'ltp'","timestamp":"2023-12-29 19:53:22,677+0530","service":"FyersDataSocket","exception":"Traceback (most recent call last):\n  File \"C:\\Python\\Lib\\site-packages\\fyers_apiv3\\FyersWebsocket\\data_ws.py\", line 1418, in On_message\n    self.OnMessage(message)\n  File \"C:\\Users\\jaypa\\AppData\\Local\\Temp\\ipykernel_13716\\3377351801.py\", line 4, in onmessage\n    Live_data(message)\n  File \"C:\\Users\\jaypa\\AppData\\Local\\Temp\\ipykernel_13716\\1689538537.py\", line 2, in Live_data\n    ltp = data['ltp']\n          ~~~~^^^^^^^\nKeyError: 'ltp'","exception_name":"KeyError"}
{"level":"ERROR","location":"[On_message:1427] data_ws","message":"'ltp'","timestamp":"2023-12-29 19:53:22,681+0530","service":"FyersDataSocket","exception":"Traceback (most recent call last):\n  File \"C:\\Python\\Lib\\site-packages\\fyers_apiv3\\FyersWebsocket\\data_ws.py\", line 1418, in On_message\n    self.OnMessage(message)\n  File \"C:\\Users\\jaypa\\AppData\\Local\\Temp\\ipykernel_13716\\3377351801.py\", line 4, in onmessage\n    Live_data(message)\n  File \"C:\\Users\\jaypa\\AppData\\Local\\Temp\\ipykernel_13716\\1689538537.py\", line 2, in Live_data\n    ltp = data['ltp']\n          ~~~~^^^^^^^\nKeyError: 'ltp'","exception_name":"KeyError"}
{"level":"ERROR","location":"[On_message:1427] data_ws","message":"'ltp'","timestamp":"2023-12-29 19:53:24,783+0530","service":"FyersDataSocket","exception":"Traceback (most recent call last):\n  File \"C:\\Python\\Lib\\site-packages\\fyers_apiv3\\FyersWebsocket\\data_ws.py\", line 1418, in On_message\n    self.OnMessage(message)\n  File \"C:\\Users\\jaypa\\AppData\\Local\\Temp\\ipykernel_13716\\3377351801.py\", line 4, in onmessage\n    Live_data(message)\n  File \"C:\\Users\\jaypa\\AppData\\Local\\Temp\\ipykernel_13716\\1689538537.py\", line 2, in Live_data\n    ltp = data['ltp']\n          ~~~~^^^^^^^\nKeyError: 'ltp'","exception_name":"KeyError"}
{"level":"ERROR","location":"[On_message:1427] data_ws","message":"'ltp'","timestamp":"2023-12-29 19:53:36,910+0530","service":"FyersDataSocket","exception":"Traceback (most recent call last):\n  File \"C:\\Python\\Lib\\site-packages\\fyers_apiv3\\FyersWebsocket\\data_ws.py\", line 1418, in On_message\n    self.OnMessage(message)\n  File \"C:\\Users\\jaypa\\AppData\\Local\\Temp\\ipykernel_13716\\3377351801.py\", line 4, in onmessage\n    Live_data(message)\n  File \"C:\\Users\\jaypa\\AppData\\Local\\Temp\\ipykernel_13716\\1689538537.py\", line 2, in Live_data\n    ltp = data['ltp']\n          ~~~~^^^^^^^\nKeyError: 'ltp'","exception_name":"KeyError"}
{"level":"ERROR","location":"[On_message:1427] data_ws","message":"'ltp'","timestamp":"2023-12-29 19:53:36,914+0530","service":"FyersDataSocket","exception":"Traceback (most recent call last):\n  File \"C:\\Python\\Lib\\site-packages\\fyers_apiv3\\FyersWebsocket\\data_ws.py\", line 1418, in On_message\n    self.OnMessage(message)\n  File \"C:\\Users\\jaypa\\AppData\\Local\\Temp\\ipykernel_13716\\3377351801.py\", line 4, in onmessage\n    Live_data(message)\n  File \"C:\\Users\\jaypa\\AppData\\Local\\Temp\\ipykernel_13716\\1689538537.py\", line 2, in Live_data\n    ltp = data['ltp']\n          ~~~~^^^^^^^\nKeyError: 'ltp'","exception_name":"KeyError"}
{"level":"ERROR","location":"[On_message:1427] data_ws","message":"'ltp'","timestamp":"2023-12-29 19:53:39,281+0530","service":"FyersDataSocket","exception":"Traceback (most recent call last):\n  File \"C:\\Python\\Lib\\site-packages\\fyers_apiv3\\FyersWebsocket\\data_ws.py\", line 1418, in On_message\n    self.OnMessage(message)\n  File \"C:\\Users\\jaypa\\AppData\\Local\\Temp\\ipykernel_13716\\3377351801.py\", line 4, in onmessage\n    Live_data(message)\n  File \"C:\\Users\\jaypa\\AppData\\Local\\Temp\\ipykernel_13716\\1689538537.py\", line 2, in Live_data\n    ltp = data['ltp']\n          ~~~~^^^^^^^\nKeyError: 'ltp'","exception_name":"KeyError"}
{"level":"ERROR","location":"[On_message:1427] data_ws","message":"'ltp'","timestamp":"2023-12-29 19:53:54,061+0530","service":"FyersDataSocket","exception":"Traceback (most recent call last):\n  File \"C:\\Python\\Lib\\site-packages\\fyers_apiv3\\FyersWebsocket\\data_ws.py\", line 1418, in On_message\n    self.OnMessage(message)\n  File \"C:\\Users\\jaypa\\AppData\\Local\\Temp\\ipykernel_13716\\3377351801.py\", line 4, in onmessage\n    Live_data(message)\n  File \"C:\\Users\\jaypa\\AppData\\Local\\Temp\\ipykernel_13716\\1689538537.py\", line 2, in Live_data\n    ltp = data['ltp']\n          ~~~~^^^^^^^\nKeyError: 'ltp'","exception_name":"KeyError"}
{"level":"ERROR","location":"[On_message:1427] data_ws","message":"'ltp'","timestamp":"2023-12-29 19:53:54,065+0530","service":"FyersDataSocket","exception":"Traceback (most recent call last):\n  File \"C:\\Python\\Lib\\site-packages\\fyers_apiv3\\FyersWebsocket\\data_ws.py\", line 1418, in On_message\n    self.OnMessage(message)\n  File \"C:\\Users\\jaypa\\AppData\\Local\\Temp\\ipykernel_13716\\3377351801.py\", line 4, in onmessage\n    Live_data(message)\n  File \"C:\\Users\\jaypa\\AppData\\Local\\Temp\\ipykernel_13716\\1689538537.py\", line 2, in Live_data\n    ltp = data['ltp']\n          ~~~~^^^^^^^\nKeyError: 'ltp'","exception_name":"KeyError"}
{"level":"ERROR","location":"[On_message:1427] data_ws","message":"'ltp'","timestamp":"2023-12-29 19:53:56,156+0530","service":"FyersDataSocket","exception":"Traceback (most recent call last):\n  File \"C:\\Python\\Lib\\site-packages\\fyers_apiv3\\FyersWebsocket\\data_ws.py\", line 1418, in On_message\n    self.OnMessage(message)\n  File \"C:\\Users\\jaypa\\AppData\\Local\\Temp\\ipykernel_13716\\3377351801.py\", line 4, in onmessage\n    Live_data(message)\n  File \"C:\\Users\\jaypa\\AppData\\Local\\Temp\\ipykernel_13716\\1689538537.py\", line 2, in Live_data\n    ltp = data['ltp']\n          ~~~~^^^^^^^\nKeyError: 'ltp'","exception_name":"KeyError"}
{"level":"ERROR","location":"[On_message:1427] data_ws","message":"'ltp'","timestamp":"2023-12-29 19:54:06,630+0530","service":"FyersDataSocket","exception":"Traceback (most recent call last):\n  File \"C:\\Python\\Lib\\site-packages\\fyers_apiv3\\FyersWebsocket\\data_ws.py\", line 1418, in On_message\n    self.OnMessage(message)\n  File \"C:\\Users\\jaypa\\AppData\\Local\\Temp\\ipykernel_13716\\3377351801.py\", line 4, in onmessage\n    Live_data(message)\n  File \"C:\\Users\\jaypa\\AppData\\Local\\Temp\\ipykernel_13716\\107485812.py\", line 2, in Live_data\n    ltp = data['ltp']\n          ~~~~^^^^^^^\nKeyError: 'ltp'","exception_name":"KeyError"}
{"level":"ERROR","location":"[On_message:1427] data_ws","message":"'ltp'","timestamp":"2023-12-29 19:54:06,669+0530","service":"FyersDataSocket","exception":"Traceback (most recent call last):\n  File \"C:\\Python\\Lib\\site-packages\\fyers_apiv3\\FyersWebsocket\\data_ws.py\", line 1418, in On_message\n    self.OnMessage(message)\n  File \"C:\\Users\\jaypa\\AppData\\Local\\Temp\\ipykernel_13716\\3377351801.py\", line 4, in onmessage\n    Live_data(message)\n  File \"C:\\Users\\jaypa\\AppData\\Local\\Temp\\ipykernel_13716\\107485812.py\", line 2, in Live_data\n    ltp = data['ltp']\n          ~~~~^^^^^^^\nKeyError: 'ltp'","exception_name":"KeyError"}
{"level":"ERROR","location":"[On_message:1427] data_ws","message":"'ltp'","timestamp":"2023-12-29 19:54:08,623+0530","service":"FyersDataSocket","exception":"Traceback (most recent call last):\n  File \"C:\\Python\\Lib\\site-packages\\fyers_apiv3\\FyersWebsocket\\data_ws.py\", line 1418, in On_message\n    self.OnMessage(message)\n  File \"C:\\Users\\jaypa\\AppData\\Local\\Temp\\ipykernel_13716\\3377351801.py\", line 4, in onmessage\n    Live_data(message)\n  File \"C:\\Users\\jaypa\\AppData\\Local\\Temp\\ipykernel_13716\\107485812.py\", line 2, in Live_data\n    ltp = data['ltp']\n          ~~~~^^^^^^^\nKeyError: 'ltp'","exception_name":"KeyError"}
{"level":"ERROR","location":"[On_message:1427] data_ws","message":"'ltp'","timestamp":"2023-12-29 20:37:34,898+0530","service":"FyersDataSocket","exception":"Traceback (most recent call last):\n  File \"C:\\Python\\Lib\\site-packages\\fyers_apiv3\\FyersWebsocket\\data_ws.py\", line 1418, in On_message\n    self.OnMessage(message)\n  File \"C:\\Users\\jaypa\\AppData\\Local\\Temp\\ipykernel_13716\\980498330.py\", line 4, in onmessage\n    Live_data(message)\n  File \"C:\\Users\\jaypa\\AppData\\Local\\Temp\\ipykernel_13716\\107485812.py\", line 2, in Live_data\n    ltp = data['ltp']\n          ~~~~^^^^^^^\nKeyError: 'ltp'","exception_name":"KeyError"}
{"level":"ERROR","location":"[On_message:1427] data_ws","message":"'ltp'","timestamp":"2023-12-29 20:37:34,905+0530","service":"FyersDataSocket","exception":"Traceback (most recent call last):\n  File \"C:\\Python\\Lib\\site-packages\\fyers_apiv3\\FyersWebsocket\\data_ws.py\", line 1418, in On_message\n    self.OnMessage(message)\n  File \"C:\\Users\\jaypa\\AppData\\Local\\Temp\\ipykernel_13716\\980498330.py\", line 4, in onmessage\n    Live_data(message)\n  File \"C:\\Users\\jaypa\\AppData\\Local\\Temp\\ipykernel_13716\\107485812.py\", line 2, in Live_data\n    ltp = data['ltp']\n          ~~~~^^^^^^^\nKeyError: 'ltp'","exception_name":"KeyError"}
{"level":"ERROR","location":"[On_message:1427] data_ws","message":"'ltp'","timestamp":"2023-12-29 20:37:36,804+0530","service":"FyersDataSocket","exception":"Traceback (most recent call last):\n  File \"C:\\Python\\Lib\\site-packages\\fyers_apiv3\\FyersWebsocket\\data_ws.py\", line 1418, in On_message\n    self.OnMessage(message)\n  File \"C:\\Users\\jaypa\\AppData\\Local\\Temp\\ipykernel_13716\\980498330.py\", line 4, in onmessage\n    Live_data(message)\n  File \"C:\\Users\\jaypa\\AppData\\Local\\Temp\\ipykernel_13716\\107485812.py\", line 2, in Live_data\n    ltp = data['ltp']\n          ~~~~^^^^^^^\nKeyError: 'ltp'","exception_name":"KeyError"}
{"level":"ERROR","location":"[On_message:1431] data_ws","message":"type object 'datetime.time' has no attribute 'localtime'","timestamp":"2023-12-29 20:37:36,977+0530","service":"FyersDataSocket","exception":"Traceback (most recent call last):\n  File \"C:\\Python\\Lib\\site-packages\\fyers_apiv3\\FyersWebsocket\\data_ws.py\", line 1418, in On_message\n    self.OnMessage(message)\n  File \"C:\\Users\\jaypa\\AppData\\Local\\Temp\\ipykernel_13716\\980498330.py\", line 4, in onmessage\n    Live_data(message)\n  File \"C:\\Users\\jaypa\\AppData\\Local\\Temp\\ipykernel_13716\\107485812.py\", line 4, in Live_data\n    t = time.localtime()\n        ^^^^^^^^^^^^^^\nAttributeError: type object 'datetime.time' has no attribute 'localtime'","exception_name":"AttributeError"}
{"level":"ERROR","location":"[On_message:1427] data_ws","message":"'ltp'","timestamp":"2023-12-29 20:38:36,621+0530","service":"FyersDataSocket","exception":"Traceback (most recent call last):\n  File \"C:\\Python\\Lib\\site-packages\\fyers_apiv3\\FyersWebsocket\\data_ws.py\", line 1418, in On_message\n    self.OnMessage(message)\n  File \"C:\\Users\\jaypa\\AppData\\Local\\Temp\\ipykernel_13716\\2276725335.py\", line 4, in onmessage\n    Live_data(message)\n  File \"C:\\Users\\jaypa\\AppData\\Local\\Temp\\ipykernel_13716\\107485812.py\", line 2, in Live_data\n    ltp = data['ltp']\n          ~~~~^^^^^^^\nKeyError: 'ltp'","exception_name":"KeyError"}
{"level":"ERROR","location":"[On_message:1427] data_ws","message":"'ltp'","timestamp":"2023-12-29 20:38:36,625+0530","service":"FyersDataSocket","exception":"Traceback (most recent call last):\n  File \"C:\\Python\\Lib\\site-packages\\fyers_apiv3\\FyersWebsocket\\data_ws.py\", line 1418, in On_message\n    self.OnMessage(message)\n  File \"C:\\Users\\jaypa\\AppData\\Local\\Temp\\ipykernel_13716\\2276725335.py\", line 4, in onmessage\n    Live_data(message)\n  File \"C:\\Users\\jaypa\\AppData\\Local\\Temp\\ipykernel_13716\\107485812.py\", line 2, in Live_data\n    ltp = data['ltp']\n          ~~~~^^^^^^^\nKeyError: 'ltp'","exception_name":"KeyError"}
{"level":"ERROR","location":"[On_message:1427] data_ws","message":"'ltp'","timestamp":"2023-12-29 20:38:38,641+0530","service":"FyersDataSocket","exception":"Traceback (most recent call last):\n  File \"C:\\Python\\Lib\\site-packages\\fyers_apiv3\\FyersWebsocket\\data_ws.py\", line 1418, in On_message\n    self.OnMessage(message)\n  File \"C:\\Users\\jaypa\\AppData\\Local\\Temp\\ipykernel_13716\\2276725335.py\", line 4, in onmessage\n    Live_data(message)\n  File \"C:\\Users\\jaypa\\AppData\\Local\\Temp\\ipykernel_13716\\107485812.py\", line 2, in Live_data\n    ltp = data['ltp']\n          ~~~~^^^^^^^\nKeyError: 'ltp'","exception_name":"KeyError"}
{"level":"ERROR","location":"[On_message:1431] data_ws","message":"type object 'datetime.time' has no attribute 'localtime'","timestamp":"2023-12-29 20:38:38,689+0530","service":"FyersDataSocket","exception":"Traceback (most recent call last):\n  File \"C:\\Python\\Lib\\site-packages\\fyers_apiv3\\FyersWebsocket\\data_ws.py\", line 1418, in On_message\n    self.OnMessage(message)\n  File \"C:\\Users\\jaypa\\AppData\\Local\\Temp\\ipykernel_13716\\2276725335.py\", line 4, in onmessage\n    Live_data(message)\n  File \"C:\\Users\\jaypa\\AppData\\Local\\Temp\\ipykernel_13716\\107485812.py\", line 4, in Live_data\n    t = time.localtime()\n        ^^^^^^^^^^^^^^\nAttributeError: type object 'datetime.time' has no attribute 'localtime'","exception_name":"AttributeError"}
{"level":"ERROR","location":"[On_message:1427] data_ws","message":"'ltp'","timestamp":"2023-12-29 20:40:00,150+0530","service":"FyersDataSocket","exception":"Traceback (most recent call last):\n  File \"C:\\Python\\Lib\\site-packages\\fyers_apiv3\\FyersWebsocket\\data_ws.py\", line 1418, in On_message\n    self.OnMessage(message)\n  File \"C:\\Users\\jaypa\\AppData\\Local\\Temp\\ipykernel_13716\\980498330.py\", line 4, in onmessage\n    Live_data(message)\n  File \"C:\\Users\\jaypa\\AppData\\Local\\Temp\\ipykernel_13716\\107485812.py\", line 2, in Live_data\n    ltp = data['ltp']\n          ~~~~^^^^^^^\nKeyError: 'ltp'","exception_name":"KeyError"}
{"level":"ERROR","location":"[On_message:1427] data_ws","message":"'ltp'","timestamp":"2023-12-29 20:40:00,155+0530","service":"FyersDataSocket","exception":"Traceback (most recent call last):\n  File \"C:\\Python\\Lib\\site-packages\\fyers_apiv3\\FyersWebsocket\\data_ws.py\", line 1418, in On_message\n    self.OnMessage(message)\n  File \"C:\\Users\\jaypa\\AppData\\Local\\Temp\\ipykernel_13716\\980498330.py\", line 4, in onmessage\n    Live_data(message)\n  File \"C:\\Users\\jaypa\\AppData\\Local\\Temp\\ipykernel_13716\\107485812.py\", line 2, in Live_data\n    ltp = data['ltp']\n          ~~~~^^^^^^^\nKeyError: 'ltp'","exception_name":"KeyError"}
{"level":"ERROR","location":"[On_message:1427] data_ws","message":"'ltp'","timestamp":"2023-12-29 20:40:01,912+0530","service":"FyersDataSocket","exception":"Traceback (most recent call last):\n  File \"C:\\Python\\Lib\\site-packages\\fyers_apiv3\\FyersWebsocket\\data_ws.py\", line 1418, in On_message\n    self.OnMessage(message)\n  File \"C:\\Users\\jaypa\\AppData\\Local\\Temp\\ipykernel_13716\\980498330.py\", line 4, in onmessage\n    Live_data(message)\n  File \"C:\\Users\\jaypa\\AppData\\Local\\Temp\\ipykernel_13716\\107485812.py\", line 2, in Live_data\n    ltp = data['ltp']\n          ~~~~^^^^^^^\nKeyError: 'ltp'","exception_name":"KeyError"}
{"level":"ERROR","location":"[On_message:1431] data_ws","message":"type object 'datetime.time' has no attribute 'localtime'","timestamp":"2023-12-29 20:40:02,113+0530","service":"FyersDataSocket","exception":"Traceback (most recent call last):\n  File \"C:\\Python\\Lib\\site-packages\\fyers_apiv3\\FyersWebsocket\\data_ws.py\", line 1418, in On_message\n    self.OnMessage(message)\n  File \"C:\\Users\\jaypa\\AppData\\Local\\Temp\\ipykernel_13716\\980498330.py\", line 4, in onmessage\n    Live_data(message)\n  File \"C:\\Users\\jaypa\\AppData\\Local\\Temp\\ipykernel_13716\\107485812.py\", line 4, in Live_data\n    t = time.localtime()\n        ^^^^^^^^^^^^^^\nAttributeError: type object 'datetime.time' has no attribute 'localtime'","exception_name":"AttributeError"}
{"level":"ERROR","location":"[On_message:1427] data_ws","message":"'ltp'","timestamp":"2023-12-29 20:40:39,643+0530","service":"FyersDataSocket","exception":"Traceback (most recent call last):\n  File \"C:\\Python\\Lib\\site-packages\\fyers_apiv3\\FyersWebsocket\\data_ws.py\", line 1418, in On_message\n    self.OnMessage(message)\n  File \"C:\\Users\\jaypa\\AppData\\Local\\Temp\\ipykernel_13716\\980498330.py\", line 4, in onmessage\n    Live_data(message)\n  File \"C:\\Users\\jaypa\\AppData\\Local\\Temp\\ipykernel_13716\\4219838404.py\", line 2, in Live_data\n    ltp = data['ltp']\n          ~~~~^^^^^^^\nKeyError: 'ltp'","exception_name":"KeyError"}
{"level":"ERROR","location":"[On_message:1427] data_ws","message":"'ltp'","timestamp":"2023-12-29 20:40:39,649+0530","service":"FyersDataSocket","exception":"Traceback (most recent call last):\n  File \"C:\\Python\\Lib\\site-packages\\fyers_apiv3\\FyersWebsocket\\data_ws.py\", line 1418, in On_message\n    self.OnMessage(message)\n  File \"C:\\Users\\jaypa\\AppData\\Local\\Temp\\ipykernel_13716\\980498330.py\", line 4, in onmessage\n    Live_data(message)\n  File \"C:\\Users\\jaypa\\AppData\\Local\\Temp\\ipykernel_13716\\4219838404.py\", line 2, in Live_data\n    ltp = data['ltp']\n          ~~~~^^^^^^^\nKeyError: 'ltp'","exception_name":"KeyError"}
{"level":"ERROR","location":"[On_message:1427] data_ws","message":"'ltp'","timestamp":"2023-12-29 20:40:42,582+0530","service":"FyersDataSocket","exception":"Traceback (most recent call last):\n  File \"C:\\Python\\Lib\\site-packages\\fyers_apiv3\\FyersWebsocket\\data_ws.py\", line 1418, in On_message\n    self.OnMessage(message)\n  File \"C:\\Users\\jaypa\\AppData\\Local\\Temp\\ipykernel_13716\\980498330.py\", line 4, in onmessage\n    Live_data(message)\n  File \"C:\\Users\\jaypa\\AppData\\Local\\Temp\\ipykernel_13716\\4219838404.py\", line 2, in Live_data\n    ltp = data['ltp']\n          ~~~~^^^^^^^\nKeyError: 'ltp'","exception_name":"KeyError"}
{"level":"ERROR","location":"[On_message:1431] data_ws","message":"type object 'datetime.time' has no attribute 'localtime'","timestamp":"2023-12-29 20:40:42,677+0530","service":"FyersDataSocket","exception":"Traceback (most recent call last):\n  File \"C:\\Python\\Lib\\site-packages\\fyers_apiv3\\FyersWebsocket\\data_ws.py\", line 1418, in On_message\n    self.OnMessage(message)\n  File \"C:\\Users\\jaypa\\AppData\\Local\\Temp\\ipykernel_13716\\980498330.py\", line 4, in onmessage\n    Live_data(message)\n  File \"C:\\Users\\jaypa\\AppData\\Local\\Temp\\ipykernel_13716\\4219838404.py\", line 4, in Live_data\n    t = time.localtime()\n        ^^^^^^^^^^^^^^\nAttributeError: type object 'datetime.time' has no attribute 'localtime'","exception_name":"AttributeError"}
