{"level":"ERROR","location":"[on_open:1503] data_ws","message":"name 'Index_Name' is not defined","timestamp":"2024-01-25 20:11:25,067+0530","service":"FyersDataSocket","exception":"Traceback (most recent call last):\n  File \"C:\\Python\\Lib\\site-packages\\fyers_apiv3\\FyersWebsocket\\data_ws.py\", line 1501, in on_open\n    self.OnOpen()\n  File \"C:\\Users\\jaypa\\AppData\\Local\\Temp\\ipykernel_8528\\576224278.py\", line 18, in onopen\n    symbols = Index_Name\n              ^^^^^^^^^^\nNameError: name 'Index_Name' is not defined","exception_name":"NameError"}
{"level":"ERROR","location":"[On_message:1427] data_ws","message":"'symbol'","timestamp":"2024-01-25 20:22:17,986+0530","service":"FyersDataSocket","exception":"Traceback (most recent call last):\n  File \"C:\\Python\\Lib\\site-packages\\fyers_apiv3\\FyersWebsocket\\data_ws.py\", line 1418, in On_message\n    self.OnMessage(message)\n  File \"C:\\Users\\jaypa\\AppData\\Local\\Temp\\ipykernel_8528\\3187559648.py\", line 5, in onmessage\n    if message['symbol'] =='NSE:NIFTY50-INDEX':\n       ~~~~~~~^^^^^^^^^^\nKeyError: 'symbol'","exception_name":"KeyError"}
{"level":"ERROR","location":"[On_message:1427] data_ws","message":"'symbol'","timestamp":"2024-01-25 20:22:17,994+0530","service":"FyersDataSocket","exception":"Traceback (most recent call last):\n  File \"C:\\Python\\Lib\\site-packages\\fyers_apiv3\\FyersWebsocket\\data_ws.py\", line 1418, in On_message\n    self.OnMessage(message)\n  File \"C:\\Users\\jaypa\\AppData\\Local\\Temp\\ipykernel_8528\\3187559648.py\", line 5, in onmessage\n    if message['symbol'] =='NSE:NIFTY50-INDEX':\n       ~~~~~~~^^^^^^^^^^\nKeyError: 'symbol'","exception_name":"KeyError"}
{"level":"ERROR","location":"[On_message:1427] data_ws","message":"'symbol'","timestamp":"2024-01-25 20:22:19,960+0530","service":"FyersDataSocket","exception":"Traceback (most recent call last):\n  File \"C:\\Python\\Lib\\site-packages\\fyers_apiv3\\FyersWebsocket\\data_ws.py\", line 1418, in On_message\n    self.OnMessage(message)\n  File \"C:\\Users\\jaypa\\AppData\\Local\\Temp\\ipykernel_8528\\3187559648.py\", line 5, in onmessage\n    if message['symbol'] =='NSE:NIFTY50-INDEX':\n       ~~~~~~~^^^^^^^^^^\nKeyError: 'symbol'","exception_name":"KeyError"}
{"level":"ERROR","location":"[On_message:1427] data_ws","message":"'symbol'","timestamp":"2024-01-25 20:23:44,142+0530","service":"FyersDataSocket","exception":"Traceback (most recent call last):\n  File \"C:\\Python\\Lib\\site-packages\\fyers_apiv3\\FyersWebsocket\\data_ws.py\", line 1418, in On_message\n    self.OnMessage(message)\n  File \"C:\\Users\\jaypa\\AppData\\Local\\Temp\\ipykernel_8528\\504134753.py\", line 7, in onmessage\n    if message['symbol'] =='NSE:NIFTY50-INDEX':\n       ~~~~~~~^^^^^^^^^^\nKeyError: 'symbol'","exception_name":"KeyError"}
{"level":"ERROR","location":"[On_message:1427] data_ws","message":"'symbol'","timestamp":"2024-01-25 20:23:44,148+0530","service":"FyersDataSocket","exception":"Traceback (most recent call last):\n  File \"C:\\Python\\Lib\\site-packages\\fyers_apiv3\\FyersWebsocket\\data_ws.py\", line 1418, in On_message\n    self.OnMessage(message)\n  File \"C:\\Users\\jaypa\\AppData\\Local\\Temp\\ipykernel_8528\\504134753.py\", line 7, in onmessage\n    if message['symbol'] =='NSE:NIFTY50-INDEX':\n       ~~~~~~~^^^^^^^^^^\nKeyError: 'symbol'","exception_name":"KeyError"}
{"level":"ERROR","location":"[On_message:1427] data_ws","message":"'symbol'","timestamp":"2024-01-25 20:23:46,169+0530","service":"FyersDataSocket","exception":"Traceback (most recent call last):\n  File \"C:\\Python\\Lib\\site-packages\\fyers_apiv3\\FyersWebsocket\\data_ws.py\", line 1418, in On_message\n    self.OnMessage(message)\n  File \"C:\\Users\\jaypa\\AppData\\Local\\Temp\\ipykernel_8528\\504134753.py\", line 7, in onmessage\n    if message['symbol'] =='NSE:NIFTY50-INDEX':\n       ~~~~~~~^^^^^^^^^^\nKeyError: 'symbol'","exception_name":"KeyError"}
{"level":"ERROR","location":"[On_message:1427] data_ws","message":"'s'","timestamp":"2024-01-25 20:23:46,681+0530","service":"FyersDataSocket","exception":"Traceback (most recent call last):\n  File \"C:\\Python\\Lib\\site-packages\\fyers_apiv3\\FyersWebsocket\\data_ws.py\", line 1418, in On_message\n    self.OnMessage(message)\n  File \"C:\\Users\\jaypa\\AppData\\Local\\Temp\\ipykernel_8528\\504134753.py\", line 5, in onmessage\n    if message['s'] =='ok':\n       ~~~~~~~^^^^^\nKeyError: 's'","exception_name":"KeyError"}
{"level":"ERROR","location":"[On_message:1427] data_ws","message":"'s'","timestamp":"2024-01-25 20:24:16,492+0530","service":"FyersDataSocket","exception":"Traceback (most recent call last):\n  File \"C:\\Python\\Lib\\site-packages\\fyers_apiv3\\FyersWebsocket\\data_ws.py\", line 1418, in On_message\n    self.OnMessage(message)\n  File \"C:\\Users\\jaypa\\AppData\\Local\\Temp\\ipykernel_8528\\2536031389.py\", line 5, in onmessage\n    if message['s'] =='ok':\n       ~~~~~~~^^^^^\nKeyError: 's'","exception_name":"KeyError"}
{"level":"ERROR","location":"[on_open:1503] data_ws","message":"'FyersModel' object has no attribute 'subscribe'","timestamp":"2024-01-25 22:09:56,570+0530","service":"FyersDataSocket","exception":"Traceback (most recent call last):\n  File \"C:\\Python\\Lib\\site-packages\\fyers_apiv3\\FyersWebsocket\\data_ws.py\", line 1501, in on_open\n    self.OnOpen()\n  File \"C:\\Users\\jaypa\\AppData\\Local\\Temp\\ipykernel_8528\\98957286.py\", line 25, in onopen\n    fyers.subscribe(symbols=symbols, data_type=data_type)\n    ^^^^^^^^^^^^^^^\nAttributeError: 'FyersModel' object has no attribute 'subscribe'","exception_name":"AttributeError"}
{"level":"ERROR","location":"[on_open:1503] data_ws","message":"'FyersModel' object has no attribute 'subscribe'","timestamp":"2024-01-25 23:23:33,721+0530","service":"FyersDataSocket","exception":"Traceback (most recent call last):\n  File \"C:\\Python\\Lib\\site-packages\\websocket\\_app.py\", line 428, in setSock\n    dispatcher.read(self.sock.sock, read, check)\n  File \"C:\\Python\\Lib\\site-packages\\websocket\\_app.py\", line 99, in read\n    if not read_callback():\n           ^^^^^^^^^^^^^^^\n  File \"C:\\Python\\Lib\\site-packages\\websocket\\_app.py\", line 442, in read\n    raise e\n  File \"C:\\Python\\Lib\\site-packages\\websocket\\_app.py\", line 437, in read\n    op_code, frame = self.sock.recv_data_frame(True)\n                     ^^^^^^^^^^^^^^^^^^^^^^^^^^^^^^^\n  File \"C:\\Python\\Lib\\site-packages\\websocket\\_core.py\", line 406, in recv_data_frame\n    frame = self.recv_frame()\n            ^^^^^^^^^^^^^^^^^\n  File \"C:\\Python\\Lib\\site-packages\\websocket\\_core.py\", line 445, in recv_frame\n    return self.frame_buffer.recv_frame()\n           ^^^^^^^^^^^^^^^^^^^^^^^^^^^^^^\n  File \"C:\\Python\\Lib\\site-packages\\websocket\\_abnf.py\", line 338, in recv_frame\n    self.recv_header()\n  File \"C:\\Python\\Lib\\site-packages\\websocket\\_abnf.py\", line 294, in recv_header\n    header = self.recv_strict(2)\n             ^^^^^^^^^^^^^^^^^^^\n  File \"C:\\Python\\Lib\\site-packages\\websocket\\_abnf.py\", line 373, in recv_strict\n    bytes_ = self.recv(min(16384, shortage))\n             ^^^^^^^^^^^^^^^^^^^^^^^^^^^^^^^\n  File \"C:\\Python\\Lib\\site-packages\\websocket\\_core.py\", line 529, in _recv\n    return recv(self.sock, bufsize)\n           ^^^^^^^^^^^^^^^^^^^^^^^^\n  File \"C:\\Python\\Lib\\site-packages\\websocket\\_socket.py\", line 122, in recv\n    raise WebSocketConnectionClosedException(\nwebsocket._exceptions.WebSocketConnectionClosedException: Connection to remote host was lost.\n\nDuring handling of the above exception, another exception occurred:\n\nTraceback (most recent call last):\n  File \"C:\\Python\\Lib\\site-packages\\fyers_apiv3\\FyersWebsocket\\data_ws.py\", line 1501, in on_open\n    self.OnOpen()\n  File \"C:\\Users\\jaypa\\AppData\\Local\\Temp\\ipykernel_8528\\98957286.py\", line 25, in onopen\n    fyers.subscribe(symbols=symbols, data_type=data_type)\n    ^^^^^^^^^^^^^^^\nAttributeError: 'FyersModel' object has no attribute 'subscribe'","exception_name":"AttributeError"}
{"level":"ERROR","location":"[on_open:1503] data_ws","message":"'FyersModel' object has no attribute 'subscribe'","timestamp":"2024-01-25 23:32:01,381+0530","service":"FyersDataSocket","exception":"Traceback (most recent call last):\n  File \"C:\\Python\\Lib\\site-packages\\fyers_apiv3\\FyersWebsocket\\data_ws.py\", line 1501, in on_open\n    self.OnOpen()\n  File \"C:\\Users\\jaypa\\AppData\\Local\\Temp\\ipykernel_8528\\98957286.py\", line 25, in onopen\n    fyers.subscribe(symbols=symbols, data_type=data_type)\n    ^^^^^^^^^^^^^^^\nAttributeError: 'FyersModel' object has no attribute 'subscribe'","exception_name":"AttributeError"}
{"level":"ERROR","location":"[on_open:1503] data_ws","message":"'FyersModel' object has no attribute 'subscribe'","timestamp":"2024-01-25 23:34:21,317+0530","service":"FyersDataSocket","exception":"Traceback (most recent call last):\n  File \"C:\\Python\\Lib\\site-packages\\websocket\\_app.py\", line 428, in setSock\n    dispatcher.read(self.sock.sock, read, check)\n  File \"C:\\Python\\Lib\\site-packages\\websocket\\_app.py\", line 99, in read\n    if not read_callback():\n           ^^^^^^^^^^^^^^^\n  File \"C:\\Python\\Lib\\site-packages\\websocket\\_app.py\", line 442, in read\n    raise e\n  File \"C:\\Python\\Lib\\site-packages\\websocket\\_app.py\", line 437, in read\n    op_code, frame = self.sock.recv_data_frame(True)\n                     ^^^^^^^^^^^^^^^^^^^^^^^^^^^^^^^\n  File \"C:\\Python\\Lib\\site-packages\\websocket\\_core.py\", line 406, in recv_data_frame\n    frame = self.recv_frame()\n            ^^^^^^^^^^^^^^^^^\n  File \"C:\\Python\\Lib\\site-packages\\websocket\\_core.py\", line 445, in recv_frame\n    return self.frame_buffer.recv_frame()\n           ^^^^^^^^^^^^^^^^^^^^^^^^^^^^^^\n  File \"C:\\Python\\Lib\\site-packages\\websocket\\_abnf.py\", line 338, in recv_frame\n    self.recv_header()\n  File \"C:\\Python\\Lib\\site-packages\\websocket\\_abnf.py\", line 294, in recv_header\n    header = self.recv_strict(2)\n             ^^^^^^^^^^^^^^^^^^^\n  File \"C:\\Python\\Lib\\site-packages\\websocket\\_abnf.py\", line 373, in recv_strict\n    bytes_ = self.recv(min(16384, shortage))\n             ^^^^^^^^^^^^^^^^^^^^^^^^^^^^^^^\n  File \"C:\\Python\\Lib\\site-packages\\websocket\\_core.py\", line 529, in _recv\n    return recv(self.sock, bufsize)\n           ^^^^^^^^^^^^^^^^^^^^^^^^\n  File \"C:\\Python\\Lib\\site-packages\\websocket\\_socket.py\", line 122, in recv\n    raise WebSocketConnectionClosedException(\nwebsocket._exceptions.WebSocketConnectionClosedException: Connection to remote host was lost.\n\nDuring handling of the above exception, another exception occurred:\n\nTraceback (most recent call last):\n  File \"C:\\Python\\Lib\\site-packages\\fyers_apiv3\\FyersWebsocket\\data_ws.py\", line 1501, in on_open\n    self.OnOpen()\n  File \"C:\\Users\\jaypa\\AppData\\Local\\Temp\\ipykernel_8528\\98957286.py\", line 25, in onopen\n    fyers.subscribe(symbols=symbols, data_type=data_type)\n    ^^^^^^^^^^^^^^^\nAttributeError: 'FyersModel' object has no attribute 'subscribe'","exception_name":"AttributeError"}
